// let a= 3;
try{
    console.log(a);
} catch(e){
    console.log("Caought an errror...",e);
    console.log("Error name: ", e.name);
}